<?xml version="1.0"?>
<robot name="delivery_robot" xmlns:xacro="http://www.ros.org/wiki/xacro">
    
    <!-- Properties -->
    <property name="base_width" value="0.5"/>
    <property name="base_length" value="0.7"/>
    <property name="base_height" value="0.2"/>
    <property name="wheel_radius" value="0.15"/>
    <property name="wheel_width" value="0.1"/>
    <property name="caster_radius" value="0.05"/>
    
    <!-- Materials -->
    <material name="blue">
        <color rgba="0.2 0.2 0.8 1.0"/>
    </material>
    <material name="black">
        <color rgba="0.2 0.2 0.2 1.0"/>
    </material>
    <material name="gray">
        <color rgba="0.7 0.7 0.7 1.0"/>
    </material>
    
    <!-- Base Link -->
    <link name="base_link">
        <visual>
            <geometry>
                <box size="${base_length} ${base_width} ${base_height}"/>
            </geometry>
            <material name="blue"/>
        </visual>
        <collision>
            <geometry>
                <box size="${base_length} ${base_width} ${base_height}"/>
            </geometry>
        </collision>
        <inertial>
            <mass value="20.0"/>
            <inertia ixx="0.1" ixy="0.0" ixz="0.0" iyy="0.1" iyz="0.0" izz="0.1"/>
        </inertial>
    </link>
    
    <!-- Left Wheel -->
    <link name="left_wheel">
        <visual>
            <geometry>
                <cylinder length="${wheel_width}" radius="${wheel_radius}"/>
            </geometry>
            <material name="black"/>
        </visual>
        <collision>
            <geometry>
                <cylinder length="${wheel_width}" radius="${wheel_radius}"/>
            </geometry>
        </collision>
        <inertial>
            <mass value="2.0"/>
            <inertia ixx="0.01" ixy="0.0" ixz="0.0" iyy="0.01" iyz="0.0" izz="0.01"/>
        </inertial>
    </link>
    
    <!-- Right Wheel -->
    <link name="right_wheel">
        <visual>
            <geometry>
                <cylinder length="${wheel_width}" radius="${wheel_radius}"/>
            </geometry>
            <material name="black"/>
        </visual>
        <collision>
            <geometry>
                <cylinder length="${wheel_width}" radius="${wheel_radius}"/>
            </geometry>
        </collision>
        <inertial>
            <mass value="2.0"/>
            <inertia ixx="0.01" ixy="0.0" ixz="0.0" iyy="0.01" iyz="0.0" izz="0.01"/>
        </inertial>
    </link>
    
    <!-- Caster Wheel -->
    <link name="caster_wheel">
        <visual>
            <geometry>
                <sphere radius="${caster_radius}"/>
            </geometry>
            <material name="gray"/>
        </visual>
        <collision>
            <geometry>
                <sphere radius="${caster_radius}"/>
            </geometry>
        </collision>
        <inertial>
            <mass value="0.5"/>
            <inertia ixx="0.001" ixy="0.0" ixz="0.0" iyy="0.001" iyz="0.0" izz="0.001"/>
        </inertial>
    </link>
    
    <!-- Delivery Compartment -->
    <link name="delivery_compartment">
        <visual>
            <geometry>
                <box size="0.4 0.3 0.3"/>
            </geometry>
            <origin xyz="0.0 0.0 0.25"/>
            <material name="gray"/>
        </visual>
        <collision>
            <geometry>
                <box size="0.4 0.3 0.3"/>
            </geometry>
            <origin xyz="0.0 0.0 0.25"/>
        </collision>
        <inertial>
            <mass value="5.0"/>
            <inertia ixx="0.05" ixy="0.0" ixz="0.0" iyy="0.05" iyz="0.0" izz="0.05"/>
        </inertial>
    </link>
    
    <!-- Joints -->
    <joint name="base_to_left_wheel" type="continuous">
        <parent link="base_link"/>
        <child link="left_wheel"/>
        <origin xyz="0.0 ${base_width/2 + wheel_width/2} 0.0" rpy="0 0 0"/>
        <axis xyz="0 1 0"/>
    </joint>
    
    <joint name="base_to_right_wheel" type="continuous">
        <parent link="base_link"/>
        <child link="right_wheel"/>
        <origin xyz="0.0 -${base_width/2 + wheel_width/2} 0.0" rpy="0 0 0"/>
        <axis xyz="0 1 0"/>
    </joint>
    
    <joint name="base_to_caster" type="fixed">
        <parent link="base_link"/>
        <child link="caster_wheel"/>
        <origin xyz="-${base_length/3} 0.0 -${base_height/2}"/>
    </joint>
    
    <joint name="base_to_compartment" type="fixed">
        <parent link="base_link"/>
        <child link="delivery_compartment"/>
        <origin xyz="0.1 0.0 ${base_height/2}"/>
    </joint>
    
    <!-- Transmission for controllers -->
    <transmission name="left_wheel_trans">
        <type>transmission_interface/SimpleTransmission</type>
        <joint name="base_to_left_wheel">
            <hardwareInterface>hardware_interface/VelocityJointInterface</hardwareInterface>
        </joint>
        <actuator name="left_motor">
            <mechanicalReduction>1</mechanicalReduction>
        </actuator>
    </transmission>
    
    <transmission name="right_wheel_trans">
        <type>transmission_interface/SimpleTransmission</type>
        <joint name="base_to_right_wheel">
            <hardwareInterface>hardware_interface/VelocityJointInterface</hardwareInterface>
        </joint>
        <actuator name="right_motor">
            <mechanicalReduction>1</mechanicalReduction>
        </actuator>
    </transmission>
    
    <!-- Gazebo plugins -->
    <gazebo>
        <plugin name="gazebo_ros2_control" filename="libgazebo_ros2_control.so">
            <parameters>$(find delivery_robot_description)/config/ros2_control_config.yaml</parameters>
        </plugin>
    </gazebo>
    
</robot>
